<?xml version="1.0" ?>
<!-- 
  This is not a standalone urdf for kobuki. It simply defines the 'kobuki' tag that can
  be incorporated by other urdf files (e.g. turtlebot).
  
  See kobuki_standalone.urdf.xacro for a standalone urdf to be tested with
      kobuki_description/launch/view_model.launch
 -->
<robot name="kobuki" xmlns:xacro="http://ros.org/wiki/xacro">
  <xacro:include filename="$(find kobuki_description)/urdf/common_properties.urdf.xacro"/>
  <xacro:include filename="$(find cp1_gazebo)/kobuki-indigo/kobuki_description/urdf/kobuki_gazebo.urdf.xacro"/>

  <!-- Kobuki --> 
   
  <xacro:macro name="kobuki">   
    <link name="base_footprint"/>
    <!--
       Base link is set at the bottom of the base mould.
       This is done to be compatible with the way base link
       was configured for turtlebot 1. Refer to
       
       https://github.com/turtlebot/turtlebot/issues/40
       
       To put the base link at the more oft used wheel
       axis, set the z-distance from the base_footprint
       to 0.352.
      -->
    <joint name="base_joint" type="fixed">
      <origin xyz="0 0 0.0102" rpy="0 0 0" />
      <parent link="base_footprint"/>
      <child link="base_link" />
    </joint>
    <link name="base_link">
      <visual>
        <geometry>
          <!-- new mesh -->
          <mesh filename="package://kobuki_description/meshes/main_body.dae" />
        </geometry>
        <origin xyz="0.001 0 0.05199" rpy="0 0 0"/>
      </visual>
      <collision>
        <geometry>
          <cylinder length="0.10938" radius="0.178"/>
        </geometry>
        <origin xyz="0.0 0 0.05949" rpy="0 0 0"/>
      </collision>
      <inertial>
        <!-- COM experimentally determined -->
        <origin xyz="0.01 0 0"/>
        <mass value="2.4"/> <!-- 2.4/2.6 kg for small/big battery pack -->
        <!-- Kobuki's inertia tensor is approximated by a cylinder with homogeneous mass distribution
             More details: http://en.wikipedia.org/wiki/List_of_moment_of_inertia_tensors
             m = 2.4 kg; h = 0.09 m; r = 0.175 m
             ixx = 1/12 * m * (3 * r^2 + h^2)
             iyy = 1/12 * m * (3 * r^2 + h^2)
             izz = 1/2 * m * r^2 
          -->
        <inertia ixx="0.019995" ixy="0.0" ixz="0.0"
                 iyy="0.019995" iyz="0.0" 
                 izz="0.03675" />
      </inertial>
    </link>
    
    <joint name="wheel_left_joint" type="continuous">
      <parent link="base_link"/>
      <child link="wheel_left_link"/>
      <origin xyz="0.00 ${0.23/2} 0.0250" rpy="${-M_PI/2} 0 0"/>
      <axis xyz="0 0 1"/>
    </joint>
    <link name="wheel_left_link">
      <visual>
        <geometry>
          <mesh filename="package://kobuki_description/meshes/wheel.dae"/>
        </geometry>
        <origin xyz="0 0 0" rpy="0 0 0"/>
      </visual>
      <collision>
        <geometry>
          <cylinder length="0.0206" radius="0.0352"/>
        </geometry>
        <origin rpy="0 0 0" xyz="0 0 0"/>
      </collision>
      <inertial>
        <mass value="0.01" />
        <origin xyz="0 0 0" />
        <inertia ixx="0.001" ixy="0.0" ixz="0.0"
                 iyy="0.001" iyz="0.0" 
                 izz="0.001" />
      </inertial>
    </link>
    
    <joint name="wheel_right_joint" type="continuous">
      <parent link="base_link"/>
      <child link="wheel_right_link"/>
      <origin xyz="0.00 -${0.23/2} 0.0250" rpy="${-M_PI/2} 0 0"/>
      <axis xyz="0 0 1"/>
    </joint>
    <link name="wheel_right_link">
      <visual>
        <geometry>
          <mesh filename="package://kobuki_description/meshes/wheel.dae"/>
        </geometry>
        <origin xyz="0 0 0" rpy="0 0 0"/>
      </visual>
      <collision>
        <geometry>
          <cylinder length="0.0206" radius="0.0350"/>
        </geometry>
        <origin rpy="0 0 0" xyz="0 0 0"/>
      </collision>
      <inertial>
        <mass value="0.01" />
        <origin xyz="0 0 0" />
        <inertia ixx="0.001" ixy="0.0" ixz="0.0"
                 iyy="0.001" iyz="0.0" 
                 izz="0.001" />
      </inertial>
    </link>
    
    <joint name="caster_front_joint" type="fixed">
      <parent link="base_link"/>
      <child link="caster_front_link"/>
      <origin xyz="0.115 0.0 0.007" rpy="${-M_PI/2} 0 0"/>
    </joint>
    <link name="caster_front_link">
      <collision>
        <geometry>
          <cylinder length="0.0176" radius="0.017"/>
        </geometry>
        <origin rpy="0 0 0" xyz="0 0 0"/>
      </collision>      
      <inertial>
        <mass value="0.01" />
        <origin xyz="0 0 0" />
        <inertia ixx="0.001" ixy="0.0" ixz="0.0"
                 iyy="0.001" iyz="0.0" 
                 izz="0.001" />
      </inertial>
    </link>
    
    <joint name="caster_back_joint" type="fixed">
      <parent link="base_link"/>
      <child link="caster_back_link"/>
      <origin xyz="-0.135 0.0 0.009" rpy="${-M_PI/2} 0 0"/>
    </joint>
    <link name="caster_back_link">
      <collision>
        <geometry>
          <cylinder length="0.0176" radius="0.017"/>
        </geometry>
        <origin rpy="0 0 0" xyz="0 0 0"/>
      </collision>      
      <inertial>
        <mass value="0.01" />
        <origin xyz="0 0 0" />
        <inertia ixx="0.001" ixy="0.0" ixz="0.0"
                 iyy="0.001" iyz="0.0" 
                 izz="0.001" />
      </inertial>
    </link>
    
    <!-- Kobuki's sensors -->
    <joint name="gyro_joint" type="fixed">
      <axis xyz="0 1 0"/>
      <origin xyz="0.056 0.062 0.0202" rpy="0 0 0"/>
      <parent link="base_link"/>
      <child link="gyro_link"/>
    </joint>
    <link name="gyro_link">
      <inertial>
        <mass value="0.001"/>
        <origin xyz="0 0 0" rpy="0 0 0"/>
        <inertia ixx="0.0001" ixy="0" ixz="0" 
                 iyy="0.000001" iyz="0"
                 izz="0.0001"/>
      </inertial>
    </link>

    <joint name="cliff_sensor_left_joint" type="fixed">
      <origin xyz="0.08734 0.13601 0.0214" rpy="0 ${M_PI/2} 0" />
      <parent link="base_link"/>
      <child link="cliff_sensor_left_link" />
    </joint>
    <link name="cliff_sensor_left_link">
      <inertial>
        <mass value="0.0001" />
        <origin xyz="0 0 0" />
        <inertia ixx="0.0001" ixy="0.0" ixz="0.0"
                 iyy="0.0001" iyz="0.0" 
                 izz="0.0001" />
      </inertial>
    </link>

    <joint name="cliff_sensor_right_joint" type="fixed">
      <origin xyz="0.085 -0.13601 0.0214" rpy="0 ${M_PI/2} 0" />
      <parent link="base_link"/>
      <child link="cliff_sensor_right_link" />
    </joint>
    <link name="cliff_sensor_right_link">
      <inertial>
        <mass value="0.0001" />
        <origin xyz="0 0 0" />
        <inertia ixx="0.0001" ixy="0.0" ixz="0.0"
                 iyy="0.0001" iyz="0.0" 
                 izz="0.0001" />
      </inertial>
    </link>
    
    <joint name="cliff_sensor_front_joint" type="fixed">
      <origin xyz="0.156 0.00 0.0214" rpy="0 ${M_PI/2} 0" />
      <parent link="base_link"/>
      <child link="cliff_sensor_front_link" />
    </joint>
    <link name="cliff_sensor_front_link">
      <inertial>
        <mass value="0.0001" />
        <origin xyz="0 0 0" />
        <inertia ixx="0.0001" ixy="0.0" ixz="0.0"
                 iyy="0.0001" iyz="0.0" 
                 izz="0.0001" />
      </inertial>
    </link>
    
    
    
    <!-- Kobuki Gazebo simulation details -->
    <kobuki_sim/>
    
  </xacro:macro>
  <xacro:include filename="$(find cp1_gazebo)/turtlebot_description/urdf/turtlebot_gazebo.urdf.xacro"/>
  <xacro:include filename="$(find cp1_gazebo)/turtlebot_description/urdf/turtlebot_properties.urdf.xacro"/>
 
  <xacro:property name="kinect_cam_py" value="-0.0125"/>
<!--   <xacro:macro name="sensor_kinect"> -->
  <!-- Parameterised in part by the values in turtlebot_properties.urdf.xacro -->
  
    <joint name="kinect_f_joint" type="fixed">
      <parent link="base_link"/>
      <child link="kinect_f_joint"/>
      <origin xyz="${cam_px} ${kinect_cam_py} ${cam_pz}" rpy="${cam_or} ${cam_op} ${cam_oy}"/>
      <axis xyz="0 1 0"/>
      <limit effort="0" velocity="0.0"/>
      <dynamics damping="1.0" friction="10000000.0"/>
       <dampingFactor>0.0</dampingFactor>
    </joint>
    <link name="kinect_f_joint">
      <collision>
        <geometry>
          <cylinder length="0.0206" radius="0.0350"/>
        </geometry>
        <origin rpy="0 0 0" xyz="0 0 0"/>
      </collision>
      <inertial>
        <mass value="0.0001" />
        <origin xyz="0 0 0" />
        <inertia ixx="1" ixy="0.0" ixz="0.0"
                 iyy="1" iyz="0.0" 
                 izz="1" />
      </inertial>
    </link>
    
    <joint name="kinect_y_joint" type="continuous">
      <parent link="kinect_f_joint"/>
      <child link="kinect_y_joint_link"/>
      <origin xyz="0 0 0" rpy="0 0 0"/>
      <axis xyz="0 1 0"/>
      <dynamics friction="100.0"/>
    </joint>
    <link name="kinect_y_joint_link">
      <collision>
        <origin rpy="0 0 0" xyz="0 0 0"/>
      </collision>
      <inertial>
        <mass value="0.0001" />
        <origin xyz="0 0 0" />
        <inertia ixx=".1" ixy="0.0" ixz="0.0"
                 iyy=".1" iyz="0.0" 
                 izz=".1" />
      </inertial>
    </link>

    <gazebo reference="kinect_y_joint_link">
      <dampingFactor>0.01</dampingFactor>
    </gazebo>
    
    <joint name="kinect_x_joint" type="continuous">
      <parent link="kinect_y_joint_link"/>
      <child link="kinect_x_joint_link"/>
      <origin xyz="0 0 0" rpy="0 0 0"/>
      <axis xyz="1 0 0"/>
      <limit effort="0" velocity="0.0"/>
      <dynamics damping="100.0" friction="100000.0"/>
      <dampingFactor>0.1</dampingFactor>
    </joint>
    <link name="kinect_x_joint_link">
      <collision>
        <geometry>
          <cylinder length="0.0206" radiuss="0.0350"/>
        </geometry>
        <origin rpy="0 0 0" xyz="0 0 0"/>
      </collision>
      <inertial>
        <mass value="0.0001" />
        <origin xyz="0 0 0" />
        <inertia ixx=".1" ixy="0.0" ixz="0.0"
                 iyy=".1" iyz="0.0" 
                 izz=".1" />
      </inertial>
    </link>
    
    <gazebo reference="kinect_x_joint_link">
      <gravity>0</gravity>
      <dampingFactor>0</dampingFactor>
    </gazebo>
    
    <joint name="kinect_xr_joint" type="prismatic">
      <parent link="kinect_x_joint_link"/>
      <child link="kinect_xr_joint_link"/>
      <origin xyz="0 0 0" rpy="0 0 0"/>
      <axis xyz="1 0 0"/>
      <limit effort="0" velocity="0.0" lower="-3" upper="3" />
      <dynamics damping="100.0" friction="100000.0"/>
      <dampingFactor>0.1</dampingFactor>
    </joint>
    <link name="kinect_xr_joint_link">
      <collision>
        <geometry>
          <cylinder length="0.0206" radius="0.0350"/>
        </geometry>
        <origin rpy="0 0 0" xyz="0 0 0"/>
      </collision>
      <inertial>
        <mass value="0.0001" />
        <origin xyz="0 0 0" />
        <inertia ixx=".1" ixy="0.0" ixz="0.0"
                 iyy=".1" iyz="0.0" 
                 izz=".1" />
      </inertial>
    </link>
    <gazebo reference="kinect_xr_joint_link">
      <dampingFactor>0.01</dampingFactor>
    </gazebo>
    
    <joint name="kinect_yr_joint" type="prismatic">
      <parent link="kinect_xr_joint_link"/>
      <child link="kinect_yr_joint_link"/>
      <origin xyz="0 0 0" rpy="0 0 0"/>
      <axis xyz="0 1 0"/>
      <limit effort="0" velocity="0.0" lower="-3" upper="3" />
      <dynamics damping="100.0" friction="100000.0"/>
      <dampingFactor>0.1</dampingFactor>
    </joint>
    <link name="kinect_yr_joint_link">
      <collision>
        <geometry>
          <cylinder length="0.0206" radius="0.0350"/>
        </geometry>
        <origin rpy="0 0 0" xyz="0 0 0"/>
      </collision>
      <inertial>
        <mass value="0.0001" />
        <origin xyz="0 0 0" />
        <inertia ixx=".1" ixy="0.0" ixz="0.0"
                 iyy=".1" iyz="0.0" 
                 izz=".1" />
      </inertial>
    </link>
    <gazebo reference="kinect_yr_joint_link">
      <gravity>0</gravity>
    </gazebo>
    
    <joint name="kinect_zr_joint" type="fixed">
      <parent link="kinect_yr_joint_link"/>
      <child link="kinect_zr_joint_link"/>
      <origin xyz="0 0 0" rpy="0 0 0"/>
      <axis xyz="0 0 1"/>
      <limit effort="0.00" velocity="0.00" lower="-3" upper="3" />
      <dynamics damping="0.01" friction="10000.0"/>
      
    </joint>
    <link name="kinect_zr_joint_link">
      <collision>
        <origin rpy="0 0 0" xyz="0 0 0"/>
      </collision>
      <inertial>
        <mass value="0.0001" />
        <origin xyz="0 0 0" />
        <inertia ixx=".1" ixy="0" ixz="0"
                 iyy=".1" iyz="0" 
                 izz="0" />
      </inertial>
    </link>    
    
    <gazebo reference="kinect_zr_joint_link">
      <gravity>0</gravity>
    </gazebo>

    
    
    <joint name="camera_rgb_joint" type="continuous">
      <origin xyz="0 0 0" rpy="0 0 0"/>
      <parent link="kinect_zr_joint_link"/>
      <child link="camera_rgb_frame" />
      <axis xyz="0 0 1" />
      <limit effort="30" velocity="0.0"/>
      <dynamics damping="100.0" friction="1000000.0"/>
    </joint>
    <link name="camera_rgb_frame"/>
<gazebo reference="camera_rgb_frame">
      <gravity>0</gravity>
    </gazebo>
    <joint name="camera_rgb_optical_joint" type="fixed">
      <origin xyz="0 0 0" rpy="${-M_PI/2} 0 ${-M_PI/2}" />
      <parent link="camera_rgb_frame" />
      <child link="camera_rgb_optical_frame" />
    </joint>
    <link name="camera_rgb_optical_frame"/>
<gazebo reference="camera_rgb_optical_frame">
  
      <gravity>0</gravity>
    </gazebo>
    <joint name="camera_joint" type="fixed">
      <origin xyz="-0.031 ${-kinect_cam_py} -0.016" rpy="0 0 0"/>
      <parent link="camera_rgb_frame"/>
      <child link="camera_link"/>
    </joint>  
      <link name="camera_link">
      <visual>
       <origin xyz="0 0 0" rpy="0 0 ${M_PI/2}"/>
        <geometry>
         <mesh filename="package://turtlebot_description/meshes/sensors/kinect.dae"/>
        </geometry>
      </visual>
  	  <collision>
        <origin xyz="0.0 0.0 0.0" rpy="0 0 0"/>
  	    <geometry>
  	      <box size="0.07271 0.27794 0.073"/>
  	    </geometry>
  	  </collision>
      <inertial>
      <mass value="0.01" />
      <origin xyz="0 0 0" />
      <inertia ixx="0.001" ixy="0.0" ixz="0.0" iyy="0.001" iyz="0.0" izz="0.001" />
    </inertial>
    </link>
    <gazebo reference="camera_link">
      <gravity>0</gravity>
    </gazebo>
    
    <!-- The fixed joints & links below are usually published by static_transformers launched by the OpenNi launch 
         files. However, for Gazebo simulation we need them, so we add them here.
         (Hence, don't publish them additionally!) -->
	<joint name="camera_depth_joint" type="fixed">
	  <origin xyz="0 ${2 * -kinect_cam_py} 0" rpy="0 0 0" />
	  <parent link="camera_rgb_frame" />
	  <child link="camera_depth_frame" />
	</joint>
	<link name="camera_depth_frame"/>

	<joint name="camera_depth_optical_joint" type="fixed">
	  <origin xyz="0 0 0" rpy="${-M_PI/2} 0 ${-M_PI/2}" />
	  <parent link="camera_depth_frame" />
	  <child link="camera_depth_optical_frame" />
	</joint>
	<link name="camera_depth_optical_frame"/>
	
	<!-- Kinect sensor for simulation -->
	<turtlebot_sim_3dsensor/>
<!--           </xacro:macro> -->
</robot>
